Workbook

Sheet Léeme
A1: Observatorios y portales de datos de Uruguay: inventario clasificado
A2: 170 recursos · taxonomía en facetas con correspondencia ODS · corte 08/10/2026
A4: Propósito | B4: Base única para el buscador temático y el análisis ecosistémico de cobertura. Cada recurso tiene un tema principal, temas secundarios, enfoques transversales explícitos, nivel de análisis y atributos de acceso.
A5: Inventario | B5: Registro completo. Las columnas con fondo crema se editan; las columnas en gris se calculan con fórmulas a partir de la taxonomía.
A6: Taxonomía temas | B6: 53 temas agrupados en 8 áreas, cada uno con ODS principal, metas de referencia, sinónimos de búsqueda y término para el Catálogo Nacional de Datos Abiertos.
A7: Enfoques | B7: Enfoques transversales y regla de asignación explícita.
A8: Niveles | B8: Escala de nivel de análisis (1 a 4).
A9: Cobertura temática | B9: Conteo por tema, estado de cobertura y alerta de concentración. Se recalcula al editar el inventario.
A10: Cobertura ODS | B10: Agregación de la cobertura por Objetivo de Desarrollo Sostenible.
A11: Cobertura enfoques | B11: Cobertura de cada enfoque transversal.
A12: Resumen | B12: Tablas de resumen: área por nivel de análisis, ámbito, tipo de recurso e instituciones con más recursos.
A13: Por confirmar | B13: Iniciativas sin portal público confirmado; no suman al inventario.
A14: Metodología | B14: Criterios del relevamiento original y criterios nuevos de clasificación y cobertura.
A15: Cómo agregar un recurso | B15: Copiar la última fila del inventario, completar las columnas crema y elegir tema principal, nivel y atributos en las listas desplegables. Los temas secundarios y enfoques se escriben como códigos separados por punto y coma (por ejemplo: T14; T25 / E01; E09).

Sheet Inventario
A1: ID | B1: Portal o recurso | C1: Institución responsable | D1: Ámbito | E1: Naturaleza institucional | F1: Tipo de recurso | G1: Alcance territorial | H1: Descripción breve | I1: Enlace | J1: Tema principal | K1: Código tema | L1: Temas secundarios (códigos) | M1: Todos los temas | N1: Área | O1: ODS principal | P1: Enfoques transversales | Q1: Nivel de análisis | R1: Descarga de datos | S1: API | T1: Desagregación territorial | U1: Desagregación por sexo | V1: Período de datos comprobado | W1: Vigencia comprobada | X1: Publicación / actualización comprobada | Y1: Portal o sistema relacionado | Z1: Notas de verificación | AA1: Fuentes de verificación | AB1: Fecha de relevamiento | AC1: Categoría original | AD1: Etiquetas originales | AE1: Incorporación
A2: UY-001 | B2: Análisis y estadísticas agropecuarias — OPYPA | C2: MGAP / OPYPA | D2: Nacional | E2: Público nacional | F2: Repositorio estadístico | G2: Nacional | H2: Análisis anual de cadenas agropecuarias, coyuntura y políticas sectoriales. | I2: https://www.gub.uy/ministerio-ganaderia-agricultura-pesca/opypa | J2: T04 · Agro y cadenas agroindustriales | K2: =LEFT(J2,3) -> T04 | L2: T01 | M2: =IF(L2="",K2,K2&"; "&L2) -> T04; T01 | N2: =INDEX('Taxonomía temas'!$D$2:$D$54,MATCH(K2,'Taxonomía temas'!$A$2:$A$54,0)) -> Economía y producción | O2: =INDEX('Taxonomía temas'!$F$2:$F$54,MATCH(K2,'Taxonomía temas'!$A$2:$A$54,0)) -> 2 | Q2: 4 · Análisis e informes | R2: Por verificar | S2: Por verificar | T2: Por verificar | U2: Por verificar | V2: 2025: anuario | W2: =IF(V2="","No","Sí") -> Sí | Z2: Repositorio de estudios; no equivale a un tablero en tiempo real. | AA2: https://www.gub.uy/ministerio-ganaderia-agricultura-pesca/opypa | AB2: 2026-10-02 | AC2: Productivo y económico | AD2: agro; economía; políticas; sectores | AE2: Relevamiento 02/10/2026
A3: UY-002 | B3: Centro de Información | C3: Uruguay XXI | D3: Nacional | E3: Público no estatal | F3: Portal estadístico | G3: Nacional | H3: Reúne informes comerciales, sectoriales, de inversión y herramientas estadísticas. | I3: https://www.uruguayxxi.gub.uy/es/centro-informacion/ | J3: T03 · Comercio exterior e inversión | K3: =LEFT(J3,3) -> T03 | L3: T07 | M3: =IF(L3="",K3,K3&"; "&L3) -> T03; T07 | N3: =INDEX('Taxonomía temas'!$D$2:$D$54,MATCH(K3,'Taxonomía temas'!$A$2:$A$54,0)) -> Economía y producción | O3: =INDEX('Taxonomía temas'!$F$2:$F$54,MATCH(K3,'Taxonomía temas'!$A$2:$A$54,0)) -> 17 | Q3: 4 · Análisis e informes | R3: Por verificar | S3: Por verificar | T3: Por verificar | U3: Por verificar | V3: Septiembre 2026: exportaciones | W3: =IF(V3="","No","Sí") -> Sí | Z3: Combina informes recurrentes y aplicaciones interactivas. | AA3: https://www.uruguayxxi.gub.uy/es/centro-informacion/ | AB3: 2026-10-02 | AC3: Productivo y económico | AD3: exportaciones; inversión; sectores; comercio-exterior | AE3: Relevamiento 02/10/2026
A4: UY-003 | B4: Centro de Información Logística | C4: INALOG | D4: Nacional | E4: Público no estatal | F4: Portal estadístico | G4: Nacional | H4: Informes sectoriales, análisis y estadísticas de operaciones logísticas del país. | I4: https://www.inalog.org.uy/centro-de-informacion/ | J4: T08 · Logística, transporte de cargas e infraestructura | K4: =LEFT(J4,3) -> T08 | L4: T03 | M4: =IF(L4="",K4,K4&"; "&L4) -> T08; T03 | N4: =INDEX('Taxonomía temas'!$D$2:$D$54,MATCH(K4,'Taxonomía temas'!$A$2:$A$54,0)) -> Economía y producción | O4: =INDEX('Taxonomía temas'!$F$2:$F$54,MATCH(K4,'Taxonomía temas'!$A$2:$A$54,0)) -> 9 | Q4: 2 · Indicadores y series | R4: Por verificar | S4: Por verificar | T4: Por verificar | U4: Por verificar | W4: =IF(V4="","No","Sí") -> No | Z4: El Sistema de Información Logística alimenta estudios; no se confirmó acceso público integral a su base. | AA4: https://www.inalog.org.uy/centro-de-informacion/ | AB4: 2026-10-02 | AC4: Productivo y económico | AD4: logística; puertos; cargas; comercio-exterior | AE4: Relevamiento 02/10/2026
A5: UY-004 | B5: Datos y estadísticas económicas | C5: MEF | D5: Nacional | E5: Público nacional | F5: Portal estadístico | G5: Nacional | H5: Información fiscal, deuda y otras series económicas del Ministerio de Economía y Finanzas. | I5: https://www.gub.uy/ministerio-economia-finanzas/datos-y-estadisticas/datos | J5: T02 · Finanzas públicas, tributación y presupuesto | K5: =LEFT(J5,3) -> T02 | L5: T01 | M5: =IF(L5="",K5,K5&"; "&L5) -> T02; T01 | N5: =INDEX('Taxonomía temas'!$D$2:$D$54,MATCH(K5,'Taxonomía temas'!$A$2:$A$54,0)) -> Economía y producción | O5: =INDEX('Taxonomía temas'!$F$2:$F$54,MATCH(K5,'Taxonomía temas'!$A$2:$A$54,0)) -> 17 | Q5: 2 · Indicadores y series | R5: Por verificar | S5: Por verificar | T5: Por verificar | U5: Por verificar | V5: Agosto 2026: resultado fiscal | W5: =IF(V5="","No","Sí") -> Sí | Z5: Las series tienen calendarios propios. | AA5: https://www.gub.uy/ministerio-economia-finanzas/datos-y-estadisticas/datos https://www.gub.uy/ministerio-economia-finanzas/ | AB5: 2026-10-02 | AC5: Productivo y económico | AD5: finanzas-públicas; macroeconomía; deuda | AE5: Relevamiento 02/10/2026
A6: UY-005 | B6: Estadísticas agropecuarias — DIEA | C6: MGAP / DIEA | D6: Nacional | E6: Público nacional | F6: Portal estadístico | G6: Nacional y departamental | H6: Censos, encuestas, anuarios y estadísticas de producción y mercado de tierras. | I6: https://www.gub.uy/ministerio-ganaderia-agricultura-pesca/diea | J6: T04 · Agro y cadenas agroindustriales | K6: =LEFT(J6,3) -> T04 | M6: =IF(L6="",K6,K6&"; "&L6) -> T04 | N6: =INDEX('Taxonomía temas'!$D$2:$D$54,MATCH(K6,'Taxonomía temas'!$A$2:$A$54,0)) -> Economía y producción | O6: =INDEX('Taxonomía temas'!$F$2:$F$54,MATCH(K6,'Taxonomía temas'!$A$2:$A$54,0)) -> 2 | Q6: 2 · Indicadores y series | R6: Por verificar | S6: Por verificar | T6: Por verificar | U6: Por verificar | V6: 2025: arrendamientos; 2024: censo | W6: =IF(V6="","No","Sí") -> Sí | X6: 2026-09-09 | Z6: Fecha indicada: publicación sobre arrendamientos 2025. | AA6: https://www.gub.uy/ministerio-ganaderia-agricultura-pesca/diea | AB6: 2026-10-02 | AC6: Productivo y económico | AD6: agro; tierras; censo-agropecuario; producción | AE6: Relevamiento 02/10/2026
A7: UY-006 | B7: Estadísticas de comercio y operaciones aduaneras | C7: Dirección Nacional de Aduanas | D7: Nacional | E7: Público nacional | F7: Portal estadístico | G7: Nacional | H7: Estadísticas de declaraciones aduaneras, movimientos comerciales y otros procedimientos. | I7: https://www.aduanas.gub.uy/innovaportal/v/4239/4/innova.front/estadisticas.html | J7: T03 · Comercio exterior e inversión | K7: =LEFT(J7,3) -> T03 | M7: =IF(L7="",K7,K7&"; "&L7) -> T03 | N7: =INDEX('Taxonomía temas'!$D$2:$D$54,MATCH(K7,'Taxonomía temas'!$A$2:$A$54,0)) -> Economía y producción | O7: =INDEX('Taxonomía temas'!$F$2:$F$54,MATCH(K7,'Taxonomía temas'!$A$2:$A$54,0)) -> 17 | Q7: 2 · Indicadores y series | R7: Por verificar | S7: Por verificar | T7: Por verificar | U7: Por verificar | W7: =IF(V7="","No","Sí") -> No | Z7: Conjuntos y períodos heterogéneos. | AA7: https://www.aduanas.gub.uy/innovaportal/v/4239/4/innova.front/estadisticas.html | AB7: 2026-10-02 | AC7: Productivo y económico | AD7: aduanas; comercio-exterior; encomiendas; incautaciones | AE7: Relevamiento 02/10/2026
A8: UY-007 | B8: Estadísticas de telecomunicaciones | C8: URSEC | D8: Nacional | E8: Público nacional | F8: Portal estadístico | G8: Nacional | H8: Informes e indicadores del mercado de telecomunicaciones. | I8: https://www.gub.uy/unidad-reguladora-servicios-comunicaciones/tematica/servicios-telecomunicaciones | J8: T10 · Telecomunicaciones y sociedad digital | K8: =LEFT(J8,3) -> T10 | M8: =IF(L8="",K8,K8&"; "&L8) -> T10 | N8: =INDEX('Taxonomía temas'!$D$2:$D$54,MATCH(K8,'Taxonomía temas'!$A$2:$A$54,0)) -> Ciencia, tecnología e innovación | O8: =INDEX('Taxonomía temas'!$F$2:$F$54,MATCH(K8,'Taxonomía temas'!$A$2:$A$54,0)) -> 9 | Q8: 2 · Indicadores y series | R8: Por verificar | S8: Por verificar | T8: Por verificar | U8: Por verificar | V8: Diciembre 2025 | W8: =IF(V8="","No","Sí") -> Sí | X8: 2026-07-10 | Z8: Fecha de publicación del informe con datos a diciembre de 2025. | AA8: https://www.gub.uy/unidad-reguladora-servicios-comunicaciones/tematica/servicios-telecomunicaciones | AB8: 2026-10-02 | AC8: Productivo y económico | AD8: telecomunicaciones; conectividad; mercados; digital | AE8: Relevamiento 02/10/2026
A9: UY-008 | B9: Estadísticas e indicadores económicos | C9: BCU | D9: Nacional | E9: Público nacional | F9: Portal estadístico | G9: Nacional | H9: Series monetarias, financieras, cambiarias, de actividad y de relaciones económicas con el exterior. | I9: https://www.bcu.gub.uy/Estadisticas-e-Indicadores/Paginas/default.aspx | J9: T01 · Macroeconomía y cuentas nacionales | K9: =LEFT(J9,3) -> T01 | L9: T03 | M9: =IF(L9="",K9,K9&"; "&L9) -> T01; T03 | N9: =INDEX('Taxonomía temas'!$D$2:$D$54,MATCH(K9,'Taxonomía temas'!$A$2:$A$54,0)) -> Economía y producción | O9: =INDEX('Taxonomía temas'!$F$2:$F$54,MATCH(K9,'Taxonomía temas'!$A$2:$A$54,0)) -> 8 | Q9: 2 · Indicadores y series | R9: Por verificar | S9: Por verificar | T9: Por verificar | U9: Por verificar | V9: Junio 2026: IMAE | W9: =IF(V9="","No","Sí") -> Sí | Z9: El período indicado corresponde a una serie, no a todas. | AA9: https://www.bcu.gub.uy/Estadisticas-e-Indicadores/Paginas/default.aspx | AB9: 2026-10-02 | AC9: Productivo y económico | AD9: macroeconomía; cuentas-nacionales; finanzas; sector-externo | AE9: Relevamiento 02/10/2026
A10: UY-009 | B10: Estadísticas portuarias de Montevideo | C10: Administración Nacional de Puertos | D10: Nacional | E10: Público nacional | F10: Repositorio estadístico | G10: Puerto de Montevideo | H10: Series mensuales de operaciones y tráfico portuario. | I10: https://anp.com.uy/index.php/es/inicio/puertos/comerciales/montevideo/estadisticas/estadistica-por-mes-unidad-gestion-de-trafico | J10: T08 · Logística, transporte de cargas e infraestructura | K10: =LEFT(J10,3) -> T08 | L10: T03 | M10: =IF(L10="",K10,K10&"; "&L10) -> T08; T03 | N10: =INDEX('Taxonomía temas'!$D$2:$D$54,MATCH(K10,'Taxonomía temas'!$A$2:$A$54,0)) -> Economía y producción | O10: =INDEX('Taxonomía temas'!$F$2:$F$54,MATCH(K10,'Taxonomía temas'!$A$2:$A$54,0)) -> 9 | Q10: 2 · Indicadores y series | R10: Por verificar | S10: Por verificar | T10: Por verificar | U10: Por verificar | V10: Junio 2026 | W10: =IF(V10="","No","Sí") -> Sí | Z10: Alcance del enlace: Unidad de Gestión de Tráfico de Montevideo. | AA10: https://anp.com.uy/index.php/es/inicio/puertos/comerciales/montevideo/estadisticas/estadistica-por-mes-unidad-gestion-de-trafico | AB10: 2026-10-02 | AC10: Productivo y económico | AD10: puertos; logística; cargas; transporte | AE10: Relevamiento 02/10/2026
A11: UY-010 | B11: Estadísticas vitivinícolas | C11: INAVI | D11: Nacional | E11: Público no estatal | F11: Portal estadístico | G11: Nacional | H11: Información estadística de viñedos, elaboración, existencias, comercialización y comercio exterior. | I11: https://inavi.com.uy/estadisticas/ | J11: T04 · Agro y cadenas agroindustriales | K11: =LEFT(J11,3) -> T04 | L11: T03 | M11: =IF(L11="",K11,K11&"; "&L11) -> T04; T03 | N11: =INDEX('Taxonomía temas'!$D$2:$D$54,MATCH(K11,'Taxonomía temas'!$A$2:$A$54,0)) -> Economía y producción | O11: =INDEX('Taxonomía temas'!$F$2:$F$54,MATCH(K11,'Taxonomía temas'!$A$2:$A$54,0)) -> 2 | Q11: 2 · Indicadores y series | R11: Por verificar | S11: Por verificar | T11: Por verificar | U11: Por verificar | W11: =IF(V11="","No","Sí") -> No | Z11: Años disponibles mediante selección; último año no comprobado. | AA11: https://inavi.com.uy/estadisticas/ | AB11: 2026-10-02 | AC11: Productivo y económico | AD11: vitivinicultura; producción; ventas; exportaciones | AE11: Relevamiento 02/10/2026
A12: UY-011 | B12: Estudios económicos de la construcción | C12: Cámara de la Construcción del Uruguay | D12: Nacional | E12: Sector empresarial | F12: Repositorio estadístico | G12: Nacional | H12: Informes de actividad, empleo, precios, mercado inmobiliario y accidentes del sector. | I12: https://sitio.ccu.com.uy/estudios-economicos/ | J12: T09 · Precios, consumo y construcción | K12: =LEFT(J12,3) -> T09 | L12: T14 | M12: =IF(L12="",K12,K12&"; "&L12) -> T09; T14 | N12: =INDEX('Taxonomía temas'!$D$2:$D$54,MATCH(K12,'Taxonomía temas'!$A$2:$A$54,0)) -> Economía y producción | O12: =INDEX('Taxonomía temas'!$F$2:$F$54,MATCH(K12,'Taxonomía temas'!$A$2:$A$54,0)) -> 12 | Q12: 4 · Análisis e informes | R12: Por verificar | S12: Por verificar | T12: Por verificar | U12: Por verificar | V12: Abril 2025: índices de precios | W12: =IF(V12="","No","Sí") -> Sí | Z12: Período confirmado solo para los índices encontrados. | AA12: https://sitio.ccu.com.uy/estudios-economicos/ https://sitio.ccu.com.uy/estudios-economicos/precios-indicadores-financieros-y-de-interes/indicadores-de-precios/ | AB12: 2026-10-02 | AC12: Productivo y económico | AD12: construcción; empleo; precios; inmuebles | AE12: Relevamiento 02/10/2026
A13: UY-012 | B13: Explorador de datos forestales | C13: MGAP / Dirección General Forestal | D13: Nacional | E13: Público nacional | F13: Visualizador | G13: Nacional y departamental | H13: Consulta visual de superficie forestal, producción y comercio de productos forestales. | I13: https://www.gub.uy/ministerio-ganaderia-agricultura-pesca/pagina-embebida/datos-forestales | J13: T04 · Agro y cadenas agroindustriales | K13: =LEFT(J13,3) -> T04 | L13: T03 | M13: =IF(L13="",K13,K13&"; "&L13) -> T04; T03 | N13: =INDEX('Taxonomía temas'!$D$2:$D$54,MATCH(K13,'Taxonomía temas'!$A$2:$A$54,0)) -> Economía y producción | O13: =INDEX('Taxonomía temas'!$F$2:$F$54,MATCH(K13,'Taxonomía temas'!$A$2:$A$54,0)) -> 2 | Q13: 3 · Visualización interactiva | R13: Por verificar | S13: Por verificar | T13: Por verificar | U13: Por verificar | V13: 2025; cartografía 2024 | W13: =IF(V13="","No","Sí") -> Sí | X13: 2026-08-11 | Z13: Lanzamiento del explorador en agosto de 2026; incluye series desde 1975. | AA13: https://www.gub.uy/ministerio-ganaderia-agricultura-pesca/pagina-embebida/datos-forestales https://www.gub.uy/ministerio-ganaderia-agricultura-pesca/noticias/explorador-interactivo-forestal | AB13: 2026-10-02 | AC13: Productivo y económico | AD13: forestación; superficie; producción; exportaciones | AE13: Relevamiento 02/10/2026
A14: UY-013 | B14: Indicadores del sector lácteo | C14: INALE | D14: Nacional | E14: Público no estatal | F14: Portal estadístico | G14: Nacional | H14: Indicadores sobre producción, remisión, precios y comercio de productos lácteos. | I14: https://www.inale.org/ | J14: T04 · Agro y cadenas agroindustriales | K14: =LEFT(J14,3) -> T04 | L14: T03 | M14: =IF(L14="",K14,K14&"; "&L14) -> T04; T03 | N14: =INDEX('Taxonomía temas'!$D$2:$D$54,MATCH(K14,'Taxonomía temas'!$A$2:$A$54,0)) -> Economía y producción | O14: =INDEX('Taxonomía temas'!$F$2:$F$54,MATCH(K14,'Taxonomía temas'!$A$2:$A$54,0)) -> 2 | Q14: 2 · Indicadores y series | R14: Por verificar | S14: Por verificar | T14: Por verificar | U14: Por verificar | V14: Septiembre 2026: indicadores mensuales | W14: =IF(V14="","No","Sí") -> Sí | X14: 2026-10-01 | Z14: Acceso desde la portada institucional; cada serie tiene su propio corte. | AA14: https://www.inale.org/ | AB14: 2026-10-02 | AC14: Productivo y económico | AD14: lechería; precios; remisión; exportaciones | AE14: Relevamiento 02/10/2026
A15: UY-014 | B15: Monitor de Coyuntura Económica | C15: Universidad Católica del Uruguay | D15: Nacional | E15: Académico | F15: Monitor | G15: Nacional | H15: Seguimiento periódico de indicadores económicos y análisis de coyuntura. | I15: https://www.ucu.edu.uy/Institucionales/MONITOR-DE-COYUNTURA-uc1457 | J15: T01 · Macroeconomía y cuentas nacionales | K15: =LEFT(J15,3) -> T01 | L15: T14; T09 | M15: =IF(L15="",K15,K15&"; "&L15) -> T01; T14; T09 | N15: =INDEX('Taxonomía temas'!$D$2:$D$54,MATCH(K15,'Taxonomía temas'!$A$2:$A$54,0)) -> Economía y producción | O15: =INDEX('Taxonomía temas'!$F$2:$F$54,MATCH(K15,'Taxonomía temas'!$A$2:$A$54,0)) -> 8 | Q15: 4 · Análisis e informes | R15: Por verificar | S15: Por verificar | T15: Por verificar | U15: Por verificar | W15: =IF(V15="","No","Sí") -> No | X15: 2026-09-29 | Z15: Fecha de publicación del monitor; último período de cada serie no auditado. | AA15: https://www.ucu.edu.uy/Institucionales/MONITOR-DE-COYUNTURA-uc1457 | AB15: 2026-10-02 | AC15: Productivo y económico | AD15: macroeconomía; actividad; empleo; precios | AE15: Relevamiento 02/10/2026
A16: UY-015 | B16: Monitor de Inversión Extranjera Directa | C16: Uruguay XXI | D16: Nacional | E16: Público no estatal | F16: Repositorio estadístico | G16: Nacional | H16: Informes periódicos sobre inversión extranjera y empresas internacionales en Uruguay. | I16: https://www.uruguayxxi.gub.uy/es/centro-informacion/inversor/informes/informes-de-mensual/ | J16: T03 · Comercio exterior e inversión | K16: =LEFT(J16,3) -> T03 | L16: T07 | M16: =IF(L16="",K16,K16&"; "&L16) -> T03; T07 | N16: =INDEX('Taxonomía temas'!$D$2:$D$54,MATCH(K16,'Taxonomía temas'!$A$2:$A$54,0)) -> Economía y producción | O16: =INDEX('Taxonomía temas'!$F$2:$F$54,MATCH(K16,'Taxonomía temas'!$A$2:$A$54,0)) -> 17 | Q16: 4 · Análisis e informes | R16: Por verificar | S16: Por verificar | T16: Por verificar | U16: Por verificar | W16: =IF(V16="","No","Sí") -> No | Y16: Centro de Información — Uruguay XXI | Z16: Se localizó edición de abril de 2026; no se trasladó esa fecha al período de todos los datos. | AA16: https://www.uruguayxxi.gub.uy/es/centro-informacion/inversor/informes/informes-de-mensual/ | AB16: 2026-10-02 | AC16: Productivo y económico | AD16: inversión-extranjera; empresas; sector-externo | AE16: Relevamiento 02/10/2026
A17: UY-016 | B17: Monitor Macroeconómico | C17: Uruguay XXI | D17: Nacional | E17: Público no estatal | F17: Módulo | G17: Nacional | H17: Indicadores seleccionados para seguir el contexto económico uruguayo. | I17: https://www.uruguayxxi.gub.uy/es/centro-informacion/monitor-macroeconomico/ | J17: T01 · Macroeconomía y cuentas nacionales | K17: =LEFT(J17,3) -> T01 | L17: T14; T09 | M17: =IF(L17="",K17,K17&"; "&L17) -> T01; T14; T09 | N17: =INDEX('Taxonomía temas'!$D$2:$D$54,MATCH(K17,'Taxonomía temas'!$A$2:$A$54,0)) -> Economía y producción | O17: =INDEX('Taxonomía temas'!$F$2:$F$54,MATCH(K17,'Taxonomía temas'!$A$2:$A$54,0)) -> 8 | Q17: 3 · Visualización interactiva | R17: Por verificar | S17: Por verificar | T17: Por verificar | U17: Por verificar | W17: =IF(V17="","No","Sí") -> No | Y17: Centro de Información — Uruguay XXI | Z17: Consultar fecha de cada indicador. | AA17: https://www.uruguayxxi.gub.uy/es/centro-informacion/monitor-macroeconomico/ | AB17: 2026-10-02 | AC17: Productivo y económico | AD17: macroeconomía; actividad; precios; empleo | AE17: Relevamiento 02/10/2026
A18: UY-017 | B18: Monitor Mipymes | C18: ANDE | D18: Nacional | E18: Público no estatal | F18: Monitor | G18: Nacional | H18: Empresas, empleo, ventas, emprendimientos y financiamiento de las mipymes. | I18: https://monitor.ande.org.uy/home.aspx | J18: T07 · Empresas, mipymes y emprendimiento | K18: =LEFT(J18,3) -> T07 | L18: T14 | M18: =IF(L18="",K18,K18&"; "&L18) -> T07; T14 | N18: =INDEX('Taxonomía temas'!$D$2:$D$54,MATCH(K18,'Taxonomía temas'!$A$2:$A$54,0)) -> Economía y producción | O18: =INDEX('Taxonomía temas'!$F$2:$F$54,MATCH(K18,'Taxonomía temas'!$A$2:$A$54,0)) -> 8 | P18: E01 · Género | Q18: 3 · Visualización interactiva | R18: Por verificar | S18: Por verificar | T18: Por verificar | U18: Sí | V18: 2.º trimestre 2026; mayo 2026 en series mensuales | W18: =IF(V18="","No","Sí") -> Sí | Z18: Las series anuales tienen distintos rezagos: empresas y ventas 2024; empleo 2025. | AA18: https://monitor.ande.org.uy/home.aspx | AB18: 2026-10-02 | AC18: Productivo y económico | AD18: mipymes; empresas; empleo; género; microfinanzas | AE18: Relevamiento 02/10/2026
A19: UY-018 | B19: Monitoreo Industrial | C19: Cámara de Industrias del Uruguay | D19: Nacional | E19: Sector empresarial | F19: Monitor | G19: Nacional | H19: Series, encuestas e informes recurrentes sobre desempeño de la industria. | I19: https://www.ciu.com.uy/monitoreo-industrial/ | J19: T05 · Industria y manufactura | K19: =LEFT(J19,3) -> T05 | L19: T14; T03 | M19: =IF(L19="",K19,K19&"; "&L19) -> T05; T14; T03 | N19: =INDEX('Taxonomía temas'!$D$2:$D$54,MATCH(K19,'Taxonomía temas'!$A$2:$A$54,0)) -> Economía y producción | O19: =INDEX('Taxonomía temas'!$F$2:$F$54,MATCH(K19,'Taxonomía temas'!$A$2:$A$54,0)) -> 9 | Q19: 3 · Visualización interactiva | R19: Por verificar | S19: Por verificar | T19: Por verificar | U19: Por verificar | V19: Agosto 2026: comercio exterior | W19: =IF(V19="","No","Sí") -> Sí | X19: 2026-09-17 | Z19: Incluye distintas frecuencias según producto. | AA19: https://www.ciu.com.uy/monitoreo-industrial/ | AB19: 2026-10-02 | AC19: Productivo y económico | AD19: industria; precios; empleo; expectativas; comercio-exterior | AE19: Relevamiento 02/10/2026
A20: UY-019 | B20: Observatorio de Oleaginosos | C20: Mesa Tecnológica de Oleaginosos | D20: Nacional | E20: Sector empresarial | F20: Observatorio | G20: Nacional | H20: Informes e indicadores de desempeño de cultivos y cadenas de oleaginosos. | I20: https://oleaginosos.org.uy/observatorio | J20: T04 · Agro y cadenas agroindustriales | K20: =LEFT(J20,3) -> T04 | M20: =IF(L20="",K20,K20&"; "&L20) -> T04 | N20: =INDEX('Taxonomía temas'!$D$2:$D$54,MATCH(K20,'Taxonomía temas'!$A$2:$A$54,0)) -> Economía y producción | O20: =INDEX('Taxonomía temas'!$F$2:$F$54,MATCH(K20,'Taxonomía temas'!$A$2:$A$54,0)) -> 2 | Q20: 4 · Análisis e informes | R20: Por verificar | S20: Por verificar | T20: Por verificar | U20: Por verificar | V20: Zafra 2024/2025 | W20: =IF(V20="","No","Sí") -> Sí | Z20: Fuente sectorial e interinstitucional. | AA20: https://oleaginosos.org.uy/observatorio | AB20: 2026-10-02 | AC20: Productivo y económico | AD20: agricultura; oleaginosos; soja; zafras | AE20: Relevamiento 02/10/2026
A21: UY-020 | B21: Observatorio Económico de Salto | C21: Universidad Católica del Uruguay | D21: Nacional | E21: Académico | F21: Observatorio | G21: Salto y frontera | H21: Estudios e indicadores sobre economía regional y diferencias de precios en la frontera. | I21: https://www.ucu.edu.uy/Institucionales/OBSERVATORIO-ECONOMICO-DE-SALTO-uc2511 | J21: T09 · Precios, consumo y construcción | K21: =LEFT(J21,3) -> T09 | L21: T01 | M21: =IF(L21="",K21,K21&"; "&L21) -> T09; T01 | N21: =INDEX('Taxonomía temas'!$D$2:$D$54,MATCH(K21,'Taxonomía temas'!$A$2:$A$54,0)) -> Economía y producción | O21: =INDEX('Taxonomía temas'!$F$2:$F$54,MATCH(K21,'Taxonomía temas'!$A$2:$A$54,0)) -> 12 | P21: E09 · Territorial y subnacional | Q21: 4 · Análisis e informes | R21: Por verificar | S21: Por verificar | T21: Sí | U21: Por verificar | W21: =IF(V21="","No","Sí") -> No | Z21: Última edición no comprobada. | AA21: https://www.ucu.edu.uy/Institucionales/OBSERVATORIO-ECONOMICO-DE-SALTO-uc2511 | AB21: 2026-10-02 | AC21: Productivo y económico | AD21: frontera; precios; comercio; economía-regional | AE21: Relevamiento 02/10/2026
A22: UY-021 | B22: Observatorio Granjero | C22: UAM / MGAP | D22: Nacional | E22: Interinstitucional / mixto | F22: Observatorio | G22: Nacional | H22: Boletines de precios mayoristas, oferta y análisis de productos hortifrutícolas. | I22: https://uam.com.uy/boletin-de-precios-mayoristas/ | J22: T04 · Agro y cadenas agroindustriales | K22: =LEFT(J22,3) -> T04 | L22: T09 | M22: =IF(L22="",K22,K22&"; "&L22) -> T04; T09 | N22: =INDEX('Taxonomía temas'!$D$2:$D$54,MATCH(K22,'Taxonomía temas'!$A$2:$A$54,0)) -> Economía y producción | O22: =INDEX('Taxonomía temas'!$F$2:$F$54,MATCH(K22,'Taxonomía temas'!$A$2:$A$54,0)) -> 2 | Q22: 4 · Análisis e informes | R22: Por verificar | S22: Por verificar | T22: Por verificar | U22: Por verificar | W22: =IF(V22="","No","Sí") -> No | Z22: Entrada por boletines de UAM; fecha del último boletín no comprobada. | AA22: https://uam.com.uy/boletin-de-precios-mayoristas/ | AB22: 2026-10-02 | AC22: Productivo y económico | AD22: horticultura; fruticultura; precios; mercados | AE22: Relevamiento 02/10/2026
A23: UY-022 | B23: Observatorio Industrial | C23: MIEM | D23: Nacional | E23: Público nacional | F23: Observatorio | G23: Nacional | H23: Indicadores y análisis sobre actividad manufacturera, estructura industrial y desempeño sectorial. | I23: https://observatorio.miem.gub.uy/obs/ | J23: T05 · Industria y manufactura | K23: =LEFT(J23,3) -> T05 | L23: T14 | M23: =IF(L23="",K23,K23&"; "&L23) -> T05; T14 | N23: =INDEX('Taxonomía temas'!$D$2:$D$54,MATCH(K23,'Taxonomía temas'!$A$2:$A$54,0)) -> Economía y producción | O23: =INDEX('Taxonomía temas'!$F$2:$F$54,MATCH(K23,'Taxonomía temas'!$A$2:$A$54,0)) -> 9 | Q23: 4 · Análisis e informes | R23: Por verificar | S23: Por verificar | T23: Por verificar | U23: Por verificar | V23: Julio 2026: IVF | W23: =IF(V23="","No","Sí") -> Sí | Z23: Contenido indexado; el tablero dinámico no pudo auditarse íntegramente. | AA23: https://observatorio.miem.gub.uy/obs/ | AB23: 2026-10-02 | AC23: Productivo y económico | AD23: industria; producción; empleo; inversión | AE23: Relevamiento 02/10/2026
A24: UY-023 | B24: Observatorio TI | C24: CUTI | D24: Nacional | E24: Sector empresarial | F24: Observatorio | G24: Nacional | H24: Indicadores de empresas tecnológicas, talento, empleo y exportaciones del sector. | I24: https://observatorioti.cuti.org.uy/ | J24: T13 · Sector tecnológico y software | K24: =LEFT(J24,3) -> T13 | L24: T14; T03; T11 | M24: =IF(L24="",K24,K24&"; "&L24) -> T13; T14; T03; T11 | N24: =INDEX('Taxonomía temas'!$D$2:$D$54,MATCH(K24,'Taxonomía temas'!$A$2:$A$54,0)) -> Ciencia, tecnología e innovación | O24: =INDEX('Taxonomía temas'!$F$2:$F$54,MATCH(K24,'Taxonomía temas'!$A$2:$A$54,0)) -> 9 | Q24: 4 · Análisis e informes | R24: Por verificar | S24: Por verificar | T24: Por verificar | U24: Por verificar | V24: 2024: encuesta sectorial | W24: =IF(V24="","No","Sí") -> Sí | Z24: No confundir el año de publicación con el período de la encuesta. | AA24: https://observatorioti.cuti.org.uy/ | AB24: 2026-10-02 | AC24: Productivo y económico | AD24: tecnologías-digitales; software; empleo; exportaciones | AE24: Relevamiento 02/10/2026
A25: UY-024 | B25: Observatorio Turístico de Montevideo | C25: Intendencia de Montevideo | D25: Departamental | E25: Gobierno departamental | F25: Módulo | G25: Montevideo | H25: Información e indicadores para analizar el turismo del departamento. | I25: https://www.descubrimontevideo.uy/macrodatos/ | J25: T06 · Turismo | K25: =LEFT(J25,3) -> T06 | M25: =IF(L25="",K25,K25&"; "&L25) -> T06 | N25: =INDEX('Taxonomía temas'!$D$2:$D$54,MATCH(K25,'Taxonomía temas'!$A$2:$A$54,0)) -> Economía y producción | O25: =INDEX('Taxonomía temas'!$F$2:$F$54,MATCH(K25,'Taxonomía temas'!$A$2:$A$54,0)) -> 8 | P25: E09 · Territorial y subnacional | Q25: 3 · Visualización interactiva | R25: Por verificar | S25: Por verificar | T25: Sí | U25: Por verificar | W25: =IF(V25="","No","Sí") -> No | Y25: Montevidata | Z25: Se accede desde Montevidata al sitio Descubrí Montevideo. | AA25: https://www.descubrimontevideo.uy/macrodatos/ | AB25: 2026-10-02 | AC25: Productivo y económico | AD25: montevideo; turismo; visitantes; gasto | AE25: Relevamiento 02/10/2026
A26: UY-025 | B26: Observatorio Turístico Inteligente | C26: Ministerio de Turismo | D26: Nacional | E26: Público nacional | F26: Observatorio | G26: Nacional | H26: Herramientas para analizar turismo receptivo, emisivo, interno y de cruceros. | I26: https://turismo.gub.uy/observatorio/index.html | J26: T06 · Turismo | K26: =LEFT(J26,3) -> T06 | M26: =IF(L26="",K26,K26&"; "&L26) -> T06 | N26: =INDEX('Taxonomía temas'!$D$2:$D$54,MATCH(K26,'Taxonomía temas'!$A$2:$A$54,0)) -> Economía y producción | O26: =INDEX('Taxonomía temas'!$F$2:$F$54,MATCH(K26,'Taxonomía temas'!$A$2:$A$54,0)) -> 8 | Q26: 4 · Análisis e informes | R26: Por verificar | S26: Por verificar | T26: Por verificar | U26: Por verificar | V26: 1.er trimestre 2026: informe receptivo | W26: =IF(V26="","No","Sí") -> Sí | Z26: El período corresponde al informe localizado; otros paneles pueden tener distinto corte. | AA26: https://turismo.gub.uy/observatorio/index.html https://www.gub.uy/ministerio-turismo/tematica/observatorios-turisticos | AB26: 2026-10-02 | AC26: Productivo y económico | AD26: turismo; visitantes; gasto; cruceros | AE26: Relevamiento 02/10/2026
A27: UY-026 | B27: Publicaciones, informes y series de la cadena cárnica | C27: INAC | D27: Nacional | E27: Público no estatal | F27: Portal estadístico | G27: Nacional | H27: Series e informes sobre faena, precios, exportaciones y desempeño de la cadena cárnica. | I27: https://www.inac.uy/innovaportal/v/26276/37/innova.bs/publicaciones-informes-y-series | J27: T04 · Agro y cadenas agroindustriales | K27: =LEFT(J27,3) -> T04 | L27: T03; T09 | M27: =IF(L27="",K27,K27&"; "&L27) -> T04; T03; T09 | N27: =INDEX('Taxonomía temas'!$D$2:$D$54,MATCH(K27,'Taxonomía temas'!$A$2:$A$54,0)) -> Economía y producción | O27: =INDEX('Taxonomía temas'!$F$2:$F$54,MATCH(K27,'Taxonomía temas'!$A$2:$A$54,0)) -> 2 | Q27: 2 · Indicadores y series | R27: Por verificar | S27: Por verificar | T27: Por verificar | U27: Por verificar | V27: 2025: anuario | W27: =IF(V27="","No","Sí") -> Sí | Z27: Los indicadores semanales pueden ser más recientes que el anuario. | AA27: https://www.inac.uy/innovaportal/v/26276/37/innova.bs/publicaciones-informes-y-series | AB27: 2026-10-02 | AC27: Productivo y económico | AD27: ganadería; carne; faena; exportaciones; precios | AE27: Relevamiento 02/10/2026
A28: UY-027 | B28: Recaudación anual y mensual por impuesto | C28: DGI | D28: Nacional | E28: Público nacional | F28: Repositorio estadístico | G28: Nacional | H28: Series de ingresos tributarios desagregadas por impuesto y período. | I28: https://www.gub.uy/direccion-general-impositiva/datos-y-estadisticas/estadisticas/recaudacion-anual-mensual-impuesto | J28: T02 · Finanzas públicas, tributación y presupuesto | K28: =LEFT(J28,3) -> T02 | M28: =IF(L28="",K28,K28&"; "&L28) -> T02 | N28: =INDEX('Taxonomía temas'!$D$2:$D$54,MATCH(K28,'Taxonomía temas'!$A$2:$A$54,0)) -> Economía y producción | O28: =INDEX('Taxonomía temas'!$F$2:$F$54,MATCH(K28,'Taxonomía temas'!$A$2:$A$54,0)) -> 17 | Q28: 2 · Indicadores y series | R28: Por verificar | S28: Por verificar | T28: Por verificar | U28: Por verificar | V28: Julio 2026 | W28: =IF(V28="","No","Sí") -> Sí | X28: 2026-10-01 | Z28: Fecha de actualización de la página consultada. | AA28: https://www.gub.uy/direccion-general-impositiva/datos-y-estadisticas/estadisticas/recaudacion-anual-mensual-impuesto | AB28: 2026-10-02 | AC28: Productivo y económico | AD28: tributación; recaudación; finanzas-públicas | AE28: Relevamiento 02/10/2026
A29: UY-028 | B29: Series históricas agropecuarias | C29: MGAP | D29: Nacional | E29: Público nacional | F29: Base de datos | G29: Nacional | H29: Consulta de series históricas de indicadores agropecuarios. | I29: https://www.mgap.gub.uy/SeriesHistoricas/hshistoricas.aspx | J29: T04 · Agro y cadenas agroindustriales | K29: =LEFT(J29,3) -> T04 | M29: =IF(L29="",K29,K29&"; "&L29) -> T04 | N29: =INDEX('Taxonomía temas'!$D$2:$D$54,MATCH(K29,'Taxonomía temas'!$A$2:$A$54,0)) -> Economía y producción | O29: =INDEX('Taxonomía temas'!$F$2:$F$54,MATCH(K29,'Taxonomía temas'!$A$2:$A$54,0)) -> 2 | Q29: 1 · Datos | R29: Por verificar | S29: Por verificar | T29: Por verificar | U29: Por verificar | W29: =IF(V29="","No","Sí") -> No | Z29: El acceso observado solicita registro. | AA29: https://www.mgap.gub.uy/SeriesHistoricas/hshistoricas.aspx | AB29: 2026-10-02 | AC29: Productivo y económico | AD29: agro; series-históricas; producción | AE29: Relevamiento 02/10/2026
A30: UY-029 | B30: Sistema de estadísticas de comercio exterior | C30: Uruguay XXI | D30: Nacional | E30: Público no estatal | F30: Módulo | G30: Nacional | H30: Consulta de flujos comerciales por producto, mercado y período. | I30: https://herramientas.uruguayxxi.gub.uy/sistema_de_estadistica/ | J30: T03 · Comercio exterior e inversión | K30: =LEFT(J30,3) -> T03 | M30: =IF(L30="",K30,K30&"; "&L30) -> T03 | N30: =INDEX('Taxonomía temas'!$D$2:$D$54,MATCH(K30,'Taxonomía temas'!$A$2:$A$54,0)) -> Economía y producción | O30: =INDEX('Taxonomía temas'!$F$2:$F$54,MATCH(K30,'Taxonomía temas'!$A$2:$A$54,0)) -> 17 | Q30: 3 · Visualización interactiva | R30: Por verificar | S30: Por verificar | T30: Por verificar | U30: Por verificar | W30: =IF(V30="","No","Sí") -> No | Y30: Centro de Información — Uruguay XXI | Z30: Último período disponible no comprobado. | AA30: https://herramientas.uruguayxxi.gub.uy/sistema_de_estadistica/ | AB30: 2026-10-02 | AC30: Productivo y económico | AD30: exportaciones; importaciones; productos; destinos | AE30: Relevamiento 02/10/2026
A31: UY-030 | B31: Sistema de Información de Precios al Consumidor | C31: MEF / Defensa del Consumidor | D31: Nacional | E31: Público nacional | F31: Monitor | G31: Nacional | H31: Comparación de precios de productos y establecimientos para consumidores. | I31: https://www.precios.uy/ | J31: T09 · Precios, consumo y construcción | K31: =LEFT(J31,3) -> T09 | M31: =IF(L31="",K31,K31&"; "&L31) -> T09 | N31: =INDEX('Taxonomía temas'!$D$2:$D$54,MATCH(K31,'Taxonomía temas'!$A$2:$A$54,0)) -> Economía y producción | O31: =INDEX('Taxonomía temas'!$F$2:$F$54,MATCH(K31,'Taxonomía temas'!$A$2:$A$54,0)) -> 12 | Q31: 3 · Visualización interactiva | R31: Por verificar | S31: Por verificar | T31: Por verificar | U31: Por verificar | W31: =IF(V31="","No","Sí") -> No | Z31: Actualización por producto y establecimiento; último corte no comprobado. | AA31: https://www.precios.uy/ | AB31: 2026-10-02 | AC31: Productivo y económico | AD31: precios; consumo; comercio | AE31: Relevamiento 02/10/2026
A32: UY-031 | B32: Sistema Nacional de Información Agropecuaria — SNIA | C32: MGAP | D32: Nacional | E32: Público nacional | F32: Geoportal | G32: Nacional | H32: Integración de información agropecuaria y acceso a visores temáticos. | I32: https://www.snia.gub.uy/dibujos/arbol-de-visores | J32: T04 · Agro y cadenas agroindustriales | K32: =LEFT(J32,3) -> T04 | L32: T35; T37; T41 | M32: =IF(L32="",K32,K32&"; "&L32) -> T04; T35; T37; T41 | N32: =INDEX('Taxonomía temas'!$D$2:$D$54,MATCH(K32,'Taxonomía temas'!$A$2:$A$54,0)) -> Economía y producción | O32: =INDEX('Taxonomía temas'!$F$2:$F$54,MATCH(K32,'Taxonomía temas'!$A$2:$A$54,0)) -> 2 | Q32: 3 · Visualización interactiva | R32: Por verificar | S32: Por verificar | T32: Sí | U32: Por verificar | W32: =IF(V32="","No","Sí") -> No | Z32: Enlace del directorio oficial IDE; carga del destino no confirmada. | AA32: https://www.gub.uy/infraestructura-datos-espaciales/nodos-ideuy | AB32: 2026-10-02 | AC32: Productivo y económico | AD32: agro; geodatos; clima; suelos | AE32: Relevamiento 02/10/2026
A33: UY-032 | B33: Visor CONEAT, suelos y campo natural | C33: MGAP / DGRN | D33: Nacional | E33: Público nacional | F33: Geoportal | G33: Nacional | H33: Cartografía de grupos de suelos, productividad y recursos naturales de uso agropecuario. | I33: https://dgrn.mgap.gub.uy/js/visores/dgrn/ | J33: T37 · Suelos, geología y recursos naturales | K33: =LEFT(J33,3) -> T37 | L33: T04; T41 | M33: =IF(L33="",K33,K33&"; "&L33) -> T37; T04; T41 | N33: =INDEX('Taxonomía temas'!$D$2:$D$54,MATCH(K33,'Taxonomía temas'!$A$2:$A$54,0)) -> Ambiente, energía y clima | O33: =INDEX('Taxonomía temas'!$F$2:$F$54,MATCH(K33,'Taxonomía temas'!$A$2:$A$54,0)) -> 15 | Q33: 3 · Visualización interactiva | R33: Por verificar | S33: Por verificar | T33: Sí | U33: Por verificar | W33: =IF(V33="","No","Sí") -> No | Z33: La vigencia varía por capa cartográfica. | AA33: https://dgrn.mgap.gub.uy/js/visores/dgrn/ | AB33: 2026-10-02 | AC33: Productivo y económico | AD33: suelos; coneat; agro; geodatos | AE33: Relevamiento 02/10/2026
A34: UY-033 | B34: A Tu Servicio | C34: MSP / DATA Uruguay | D34: Nacional | E34: Interinstitucional / mixto | F34: Visualizador | G34: Nacional | H34: Comparación de prestadores de salud mediante indicadores de servicios, desempeño y atención. | I34: https://atuservicio.uy/ | J34: T22 · Salud y sistema sanitario | K34: =LEFT(J34,3) -> T22 | M34: =IF(L34="",K34,K34&"; "&L34) -> T22 | N34: =INDEX('Taxonomía temas'!$D$2:$D$54,MATCH(K34,'Taxonomía temas'!$A$2:$A$54,0)) -> Salud y población | O34: =INDEX('Taxonomía temas'!$F$2:$F$54,MATCH(K34,'Taxonomía temas'!$A$2:$A$54,0)) -> 3 | Q34: 3 · Visualización interactiva | R34: Por verificar | S34: Por verificar | T34: Por verificar | U34: Por verificar | W34: =IF(V34="","No","Sí") -> No | Z34: Catálogo fuente actualizado en abril de 2025; esa fecha no acredita el corte actual del sitio. | AA34: https://github.com/datauy/atuservicio https://catalogodatos.gub.uy/dataset/msp-a-tu-servicio | AB34: 2026-10-02 | AC34: Social y salud | AD34: salud; prestadores; calidad; usuarios | AE34: Relevamiento 02/10/2026
A35: UY-034 | B35: Datos abiertos de INEFOP | C35: INEFOP | D35: Nacional | E35: Público no estatal | F35: Catálogo institucional | G35: Nacional | H35: Conjuntos de datos institucionales sobre gestión y transparencia del instituto. | I35: https://catalogodatos.gub.uy/organization/instituto-nacional-de-empleo-y-formacion-profesional | J35: T21 · Formación profesional y capacitación | K35: =LEFT(J35,3) -> T21 | L35: T14; T44 | M35: =IF(L35="",K35,K35&"; "&L35) -> T21; T14; T44 | N35: =INDEX('Taxonomía temas'!$D$2:$D$54,MATCH(K35,'Taxonomía temas'!$A$2:$A$54,0)) -> Trabajo y protección social | O35: =INDEX('Taxonomía temas'!$F$2:$F$54,MATCH(K35,'Taxonomía temas'!$A$2:$A$54,0)) -> 4 | Q35: 1 · Datos | R35: Sí | S35: Por verificar | T35: Por verificar | U35: Por verificar | W35: =IF(V35="","No","Sí") -> No | Y35: Catálogo Nacional de Datos Abiertos | Z35: Se confirmó la incorporación al catálogo nacional y once conjuntos publicados; fecha por conjunto. | AA35: https://www.inefop.uy/post/inefop-se-integra-al-cat%C3%A1logo-nacional-de-datos-abiertos-y-avanza-en-apertura-de-datos | AB35: 2026-10-02 | AC35: Social y salud | AD35: formación-profesional; empleo; gestión; datos-abiertos | AE35: Relevamiento 02/10/2026
A36: UY-035 | B36: Estadísticas del mercado de trabajo | C36: MTSS / Unidad Estadística | D36: Nacional | E36: Público nacional | F36: Portal estadístico | G36: Nacional y departamental | H36: Informes y estadísticas sobre empleo, condiciones laborales y otros temas del trabajo. | I36: https://www.gub.uy/ministerio-trabajo-seguridad-social/unidad-estadistica-mtss | J36: T14 · Empleo y mercado de trabajo | K36: =LEFT(J36,3) -> T14 | L36: T15 | M36: =IF(L36="",K36,K36&"; "&L36) -> T14; T15 | N36: =INDEX('Taxonomía temas'!$D$2:$D$54,MATCH(K36,'Taxonomía temas'!$A$2:$A$54,0)) -> Trabajo y protección social | O36: =INDEX('Taxonomía temas'!$F$2:$F$54,MATCH(K36,'Taxonomía temas'!$A$2:$A$54,0)) -> 8 | Q36: 2 · Indicadores y series | R36: Por verificar | S36: Por verificar | T36: Por verificar | U36: Por verificar | V36: 2025: empleo cooperativo; 2024: accidentes | W36: =IF(V36="","No","Sí") -> Sí | Z36: Períodos diferentes según informe. | AA36: https://www.gub.uy/ministerio-trabajo-seguridad-social/unidad-estadistica-mtss https://www.gub.uy/ministerio-trabajo-seguridad-social/datos-y-estadisticas/estadisticas | AB36: 2026-10-02 | AC36: Social y salud | AD36: empleo; salarios; relaciones-laborales; accidentes | AE36: Relevamiento 02/10/2026
A37: UY-036 | B37: Estadísticas vitales | C37: Ministerio de Salud Pública | D37: Nacional | E37: Público nacional | F37: Repositorio estadístico | G37: Nacional y departamental | H37: Series y publicaciones sobre nacimientos, defunciones y otros hechos vitales. | I37: https://www.gub.uy/ministerio-salud-publica/datos-y-estadisticas/estadisticas/estadisticas-vitales | J37: T25 · Población, demografía y estadísticas vitales | K37: =LEFT(J37,3) -> T25 | L37: T22 | M37: =IF(L37="",K37,K37&"; "&L37) -> T25; T22 | N37: =INDEX('Taxonomía temas'!$D$2:$D$54,MATCH(K37,'Taxonomía temas'!$A$2:$A$54,0)) -> Salud y población | O37: =INDEX('Taxonomía temas'!$F$2:$F$54,MATCH(K37,'Taxonomía temas'!$A$2:$A$54,0)) -> 17 | Q37: 2 · Indicadores y series | R37: Por verificar | S37: Por verificar | T37: Por verificar | U37: Por verificar | W37: =IF(V37="","No","Sí") -> No | Z37: Último período disponible no comprobado en este relevamiento. | AA37: https://www.gub.uy/ministerio-salud-publica/datos-y-estadisticas/estadisticas/estadisticas-vitales | AB37: 2026-10-02 | AC37: Social y salud | AD37: salud; natalidad; mortalidad; demografía | AE37: Relevamiento 02/10/2026
A38: UY-037 | B38: Infancia en Datos | C38: UNICEF Uruguay | D38: Nacional | E38: Internacional, sección Uruguay | F38: Portal de indicadores | G38: Uruguay | H38: Presentaciones y análisis de evidencia sobre infancia, adolescencia y acceso a derechos. | I38: https://www.unicef.org/uruguay/infancia-en-datos | J38: T17 · Pobreza, desigualdad y condiciones de vida | K38: =LEFT(J38,3) -> T17 | L38: T22; T27 | M38: =IF(L38="",K38,K38&"; "&L38) -> T17; T22; T27 | N38: =INDEX('Taxonomía temas'!$D$2:$D$54,MATCH(K38,'Taxonomía temas'!$A$2:$A$54,0)) -> Trabajo y protección social | O38: =INDEX('Taxonomía temas'!$F$2:$F$54,MATCH(K38,'Taxonomía temas'!$A$2:$A$54,0)) -> 1 | P38: E02 · Infancia y adolescencia; E08 · Enfoque de derechos | Q38: 4 · Análisis e informes | R38: Por verificar | S38: Por verificar | T38: Por verificar | U38: Por verificar | V38: 2025: censo de adolescentes privados de libertad | W38: =IF(V38="","No","Sí") -> Sí | Z38: Período indicado para un estudio; otras publicaciones usan Censo 2023 y encuestas distintas. | AA38: https://www.unicef.org/uruguay/infancia-en-datos | AB38: 2026-10-02 | AC38: Social y salud | AD38: infancia; adolescencia; pobreza; salud; educación | AE38: Relevamiento 02/10/2026
A39: UY-038 | B39: Información y observación del personal de salud | C39: Ministerio de Salud Pública | D39: Nacional | E39: Público nacional | F39: Portal temático | G39: Nacional | H39: Estadísticas y estudios relativos a disponibilidad y características del personal sanitario. | I39: https://www.gub.uy/ministerio-salud-publica/personal-salud | J39: T22 · Salud y sistema sanitario | K39: =LEFT(J39,3) -> T22 | L39: T14 | M39: =IF(L39="",K39,K39&"; "&L39) -> T22; T14 | N39: =INDEX('Taxonomía temas'!$D$2:$D$54,MATCH(K39,'Taxonomía temas'!$A$2:$A$54,0)) -> Salud y población | O39: =INDEX('Taxonomía temas'!$F$2:$F$54,MATCH(K39,'Taxonomía temas'!$A$2:$A$54,0)) -> 3 | Q39: 2 · Indicadores y series | R39: Por verificar | S39: Por verificar | T39: Por verificar | U39: Por verificar | W39: =IF(V39="","No","Sí") -> No | Z39: Acceso institucional a recursos e información del área. | AA39: https://www.gub.uy/ministerio-salud-publica/personal-salud | AB39: 2026-10-02 | AC39: Social y salud | AD39: salud; recursos-humanos; empleo; profesionales | AE39: Relevamiento 02/10/2026
A40: UY-039 | B40: Informes de población y proyectos atendidos | C40: INAU | D40: Nacional | E40: Público nacional | F40: Repositorio estadístico | G40: Nacional | H40: Informes de atención y cobertura de proyectos dirigidos a niños, niñas y adolescentes. | I40: https://www.inau.gub.uy/documentos/ano-2025 | J40: T18 · Protección social y servicios sociales | K40: =LEFT(J40,3) -> T18 | M40: =IF(L40="",K40,K40&"; "&L40) -> T18 | N40: =INDEX('Taxonomía temas'!$D$2:$D$54,MATCH(K40,'Taxonomía temas'!$A$2:$A$54,0)) -> Trabajo y protección social | O40: =INDEX('Taxonomía temas'!$F$2:$F$54,MATCH(K40,'Taxonomía temas'!$A$2:$A$54,0)) -> 1 | P40: E02 · Infancia y adolescencia | Q40: 2 · Indicadores y series | R40: Por verificar | S40: Por verificar | T40: Por verificar | U40: Por verificar | V40: 2025 | W40: =IF(V40="","No","Sí") -> Sí | Z40: Enlace a la colección anual 2025. | AA40: https://www.inau.gub.uy/documentos/ano-2025 | AB40: 2026-10-02 | AC40: Social y salud | AD40: infancia; adolescencia; protección; servicios | AE40: Relevamiento 02/10/2026
...

Sheet Cobertura temática
A1: Cobertura temática del ecosistema
A2: Recursos nacionales y departamentales; las referencias internacionales se cuentan aparte. Todas las cifras son fórmulas sobre el inventario.
A4: Código | B4: Área | C4: Tema | D4: ODS | E4: Recursos (tema principal) | F4: Recursos (cualquier mención) | G4: Con análisis e informes (nivel 4) | H4: Con visualización (nivel 3) | I4: Con vigencia comprobada | J4: Referencias internacionales | K4: Estado de cobertura | L4: Concentración | M4: Datasets en Catálogo AGESIC
A5: ='Taxonomía temas'!A2 -> T01 | B5: ='Taxonomía temas'!D2 -> Economía y producción | C5: ='Taxonomía temas'!E2 -> Macroeconomía y cuentas nacionales | D5: ='Taxonomía temas'!F2 -> 8 | E5: =COUNTIFS(Inventario!$K$2:$K$1000,A5,Inventario!$D$2:$D$1000,"<>Internacional") -> 3 | F5: =COUNTIFS(Inventario!$M$2:$M$1000,"*"&A5&"*",Inventario!$D$2:$D$1000,"<>Internacional") -> 7 | G5: =COUNTIFS(Inventario!$M$2:$M$1000,"*"&A5&"*",Inventario!$D$2:$D$1000,"<>Internacional",Inventario!$Q$2:$Q$1000,"4*") -> 3 | H5: =COUNTIFS(Inventario!$M$2:$M$1000,"*"&A5&"*",Inventario!$D$2:$D$1000,"<>Internacional",Inventario!$Q$2:$Q$1000,"3*") -> 1 | I5: =COUNTIFS(Inventario!$M$2:$M$1000,"*"&A5&"*",Inventario!$D$2:$D$1000,"<>Internacional",Inventario!$W$2:$W$1000,"Sí") -> 4 | J5: =COUNTIFS(Inventario!$M$2:$M$1000,"*"&A5&"*",Inventario!$D$2:$D$1000,"Internacional") -> 2 | K5: =IF(F5=0,IF(J5>0,"Sin cobertura nacional (solo internacional)","Sin cobertura"),IF(E5=0,"Cobertura indirecta",IF(G5=0,"Cobertura sin análisis","Cobertura con análisis"))) -> Cobertura con análisis | L5: =IF(E5>=5,"Alta concentración: revisar superposición","") | M5: =HYPERLINK("https://catalogodatos.gub.uy/dataset?q="&SUBSTITUTE('Taxonomía temas'!J2," ","+"),"Buscar datasets") -> Buscar datasets
A6: ='Taxonomía temas'!A3 -> T02 | B6: ='Taxonomía temas'!D3 -> Economía y producción | C6: ='Taxonomía temas'!E3 -> Finanzas públicas, tributación y presupuesto | D6: ='Taxonomía temas'!F3 -> 17 | E6: =COUNTIFS(Inventario!$K$2:$K$1000,A6,Inventario!$D$2:$D$1000,"<>Internacional") -> 3 | F6: =COUNTIFS(Inventario!$M$2:$M$1000,"*"&A6&"*",Inventario!$D$2:$D$1000,"<>Internacional") -> 6 | G6: =COUNTIFS(Inventario!$M$2:$M$1000,"*"&A6&"*",Inventario!$D$2:$D$1000,"<>Internacional",Inventario!$Q$2:$Q$1000,"4*") -> 1 | H6: =COUNTIFS(Inventario!$M$2:$M$1000,"*"&A6&"*",Inventario!$D$2:$D$1000,"<>Internacional",Inventario!$Q$2:$Q$1000,"3*") -> 2 | I6: =COUNTIFS(Inventario!$M$2:$M$1000,"*"&A6&"*",Inventario!$D$2:$D$1000,"<>Internacional",Inventario!$W$2:$W$1000,"Sí") -> 2 | J6: =COUNTIFS(Inventario!$M$2:$M$1000,"*"&A6&"*",Inventario!$D$2:$D$1000,"Internacional") -> 0 | K6: =IF(F6=0,IF(J6>0,"Sin cobertura nacional (solo internacional)","Sin cobertura"),IF(E6=0,"Cobertura indirecta",IF(G6=0,"Cobertura sin análisis","Cobertura con análisis"))) -> Cobertura con análisis | L6: =IF(E6>=5,"Alta concentración: revisar superposición","") | M6: =HYPERLINK("https://catalogodatos.gub.uy/dataset?q="&SUBSTITUTE('Taxonomía temas'!J3," ","+"),"Buscar datasets") -> Buscar datasets
A7: ='Taxonomía temas'!A4 -> T03 | B7: ='Taxonomía temas'!D4 -> Economía y producción | C7: ='Taxonomía temas'!E4 -> Comercio exterior e inversión | D7: ='Taxonomía temas'!F4 -> 17 | E7: =COUNTIFS(Inventario!$K$2:$K$1000,A7,Inventario!$D$2:$D$1000,"<>Internacional") -> 4 | F7: =COUNTIFS(Inventario!$M$2:$M$1000,"*"&A7&"*",Inventario!$D$2:$D$1000,"<>Internacional") -> 13 | G7: =COUNTIFS(Inventario!$M$2:$M$1000,"*"&A7&"*",Inventario!$D$2:$D$1000,"<>Internacional",Inventario!$Q$2:$Q$1000,"4*") -> 3 | H7: =COUNTIFS(Inventario!$M$2:$M$1000,"*"&A7&"*",Inventario!$D$2:$D$1000,"<>Internacional",Inventario!$Q$2:$Q$1000,"3*") -> 3 | I7: =COUNTIFS(Inventario!$M$2:$M$1000,"*"&A7&"*",Inventario!$D$2:$D$1000,"<>Internacional",Inventario!$W$2:$W$1000,"Sí") -> 8 | J7: =COUNTIFS(Inventario!$M$2:$M$1000,"*"&A7&"*",Inventario!$D$2:$D$1000,"Internacional") -> 3 | K7: =IF(F7=0,IF(J7>0,"Sin cobertura nacional (solo internacional)","Sin cobertura"),IF(E7=0,"Cobertura indirecta",IF(G7=0,"Cobertura sin análisis","Cobertura con análisis"))) -> Cobertura con análisis | L7: =IF(E7>=5,"Alta concentración: revisar superposición","") | M7: =HYPERLINK("https://catalogodatos.gub.uy/dataset?q="&SUBSTITUTE('Taxonomía temas'!J4," ","+"),"Buscar datasets") -> Buscar datasets
A8: ='Taxonomía temas'!A5 -> T04 | B8: ='Taxonomía temas'!D5 -> Economía y producción | C8: ='Taxonomía temas'!E5 -> Agro y cadenas agroindustriales | D8: ='Taxonomía temas'!F5 -> 2 | E8: =COUNTIFS(Inventario!$K$2:$K$1000,A8,Inventario!$D$2:$D$1000,"<>Internacional") -> 11 | F8: =COUNTIFS(Inventario!$M$2:$M$1000,"*"&A8&"*",Inventario!$D$2:$D$1000,"<>Internacional") -> 15 | G8: =COUNTIFS(Inventario!$M$2:$M$1000,"*"&A8&"*",Inventario!$D$2:$D$1000,"<>Internacional",Inventario!$Q$2:$Q$1000,"4*") -> 3 | H8: =COUNTIFS(Inventario!$M$2:$M$1000,"*"&A8&"*",Inventario!$D$2:$D$1000,"<>Internacional",Inventario!$Q$2:$Q$1000,"3*") -> 6 | I8: =COUNTIFS(Inventario!$M$2:$M$1000,"*"&A8&"*",Inventario!$D$2:$D$1000,"<>Internacional",Inventario!$W$2:$W$1000,"Sí") -> 7 | J8: =COUNTIFS(Inventario!$M$2:$M$1000,"*"&A8&"*",Inventario!$D$2:$D$1000,"Internacional") -> 1 | K8: =IF(F8=0,IF(J8>0,"Sin cobertura nacional (solo internacional)","Sin cobertura"),IF(E8=0,"Cobertura indirecta",IF(G8=0,"Cobertura sin análisis","Cobertura con análisis"))) -> Cobertura con análisis | L8: =IF(E8>=5,"Alta concentración: revisar superposición","") -> Alta concentración: revisar superposición | M8: =HYPERLINK("https://catalogodatos.gub.uy/dataset?q="&SUBSTITUTE('Taxonomía temas'!J5," ","+"),"Buscar datasets") -> Buscar datasets
A9: ='Taxonomía temas'!A6 -> T05 | B9: ='Taxonomía temas'!D6 -> Economía y producción | C9: ='Taxonomía temas'!E6 -> Industria y manufactura | D9: ='Taxonomía temas'!F6 -> 9 | E9: =COUNTIFS(Inventario!$K$2:$K$1000,A9,Inventario!$D$2:$D$1000,"<>Internacional") -> 2 | F9: =COUNTIFS(Inventario!$M$2:$M$1000,"*"&A9&"*",Inventario!$D$2:$D$1000,"<>Internacional") -> 2 | G9: =COUNTIFS(Inventario!$M$2:$M$1000,"*"&A9&"*",Inventario!$D$2:$D$1000,"<>Internacional",Inventario!$Q$2:$Q$1000,"4*") -> 1 | H9: =COUNTIFS(Inventario!$M$2:$M$1000,"*"&A9&"*",Inventario!$D$2:$D$1000,"<>Internacional",Inventario!$Q$2:$Q$1000,"3*") -> 1 | I9: =COUNTIFS(Inventario!$M$2:$M$1000,"*"&A9&"*",Inventario!$D$2:$D$1000,"<>Internacional",Inventario!$W$2:$W$1000,"Sí") -> 2 | J9: =COUNTIFS(Inventario!$M$2:$M$1000,"*"&A9&"*",Inventario!$D$2:$D$1000,"Internacional") -> 1 | K9: =IF(F9=0,IF(J9>0,"Sin cobertura nacional (solo internacional)","Sin cobertura"),IF(E9=0,"Cobertura indirecta",IF(G9=0,"Cobertura sin análisis","Cobertura con análisis"))) -> Cobertura con análisis | L9: =IF(E9>=5,"Alta concentración: revisar superposición","") | M9: =HYPERLINK("https://catalogodatos.gub.uy/dataset?q="&SUBSTITUTE('Taxonomía temas'!J6," ","+"),"Buscar datasets") -> Buscar datasets
A10: ='Taxonomía temas'!A7 -> T06 | B10: ='Taxonomía temas'!D7 -> Economía y producción | C10: ='Taxonomía temas'!E7 -> Turismo | D10: ='Taxonomía temas'!F7 -> 8 | E10: =COUNTIFS(Inventario!$K$2:$K$1000,A10,Inventario!$D$2:$D$1000,"<>Internacional") -> 2 | F10: =COUNTIFS(Inventario!$M$2:$M$1000,"*"&A10&"*",Inventario!$D$2:$D$1000,"<>Internacional") -> 2 | G10: =COUNTIFS(Inventario!$M$2:$M$1000,"*"&A10&"*",Inventario!$D$2:$D$1000,"<>Internacional",Inventario!$Q$2:$Q$1000,"4*") -> 1 | H10: =COUNTIFS(Inventario!$M$2:$M$1000,"*"&A10&"*",Inventario!$D$2:$D$1000,"<>Internacional",Inventario!$Q$2:$Q$1000,"3*") -> 1 | I10: =COUNTIFS(Inventario!$M$2:$M$1000,"*"&A10&"*",Inventario!$D$2:$D$1000,"<>Internacional",Inventario!$W$2:$W$1000,"Sí") -> 1 | J10: =COUNTIFS(Inventario!$M$2:$M$1000,"*"&A10&"*",Inventario!$D$2:$D$1000,"Internacional") -> 0 | K10: =IF(F10=0,IF(J10>0,"Sin cobertura nacional (solo internacional)","Sin cobertura"),IF(E10=0,"Cobertura indirecta",IF(G10=0,"Cobertura sin análisis","Cobertura con análisis"))) -> Cobertura con análisis | L10: =IF(E10>=5,"Alta concentración: revisar superposición","") | M10: =HYPERLINK("https://catalogodatos.gub.uy/dataset?q="&SUBSTITUTE('Taxonomía temas'!J7," ","+"),"Buscar datasets") -> Buscar datasets
A11: ='Taxonomía temas'!A8 -> T07 | B11: ='Taxonomía temas'!D8 -> Economía y producción | C11: ='Taxonomía temas'!E8 -> Empresas, mipymes y emprendimiento | D11: ='Taxonomía temas'!F8 -> 8 | E11: =COUNTIFS(Inventario!$K$2:$K$1000,A11,Inventario!$D$2:$D$1000,"<>Internacional") -> 1 | F11: =COUNTIFS(Inventario!$M$2:$M$1000,"*"&A11&"*",Inventario!$D$2:$D$1000,"<>Internacional") -> 4 | G11: =COUNTIFS(Inventario!$M$2:$M$1000,"*"&A11&"*",Inventario!$D$2:$D$1000,"<>Internacional",Inventario!$Q$2:$Q$1000,"4*") -> 2 | H11: =COUNTIFS(Inventario!$M$2:$M$1000,"*"&A11&"*",Inventario!$D$2:$D$1000,"<>Internacional",Inventario!$Q$2:$Q$1000,"3*") -> 2 | I11: =COUNTIFS(Inventario!$M$2:$M$1000,"*"&A11&"*",Inventario!$D$2:$D$1000,"<>Internacional",Inventario!$W$2:$W$1000,"Sí") -> 2 | J11: =COUNTIFS(Inventario!$M$2:$M$1000,"*"&A11&"*",Inventario!$D$2:$D$1000,"Internacional") -> 1 | K11: =IF(F11=0,IF(J11>0,"Sin cobertura nacional (solo internacional)","Sin cobertura"),IF(E11=0,"Cobertura indirecta",IF(G11=0,"Cobertura sin análisis","Cobertura con análisis"))) -> Cobertura con análisis | L11: =IF(E11>=5,"Alta concentración: revisar superposición","") | M11: =HYPERLINK("https://catalogodatos.gub.uy/dataset?q="&SUBSTITUTE('Taxonomía temas'!J8," ","+"),"Buscar datasets") -> Buscar datasets
A12: ='Taxonomía temas'!A9 -> T08 | B12: ='Taxonomía temas'!D9 -> Economía y producción | C12: ='Taxonomía temas'!E9 -> Logística, transporte de cargas e infraestructura | D12: ='Taxonomía temas'!F9 -> 9 | E12: =COUNTIFS(Inventario!$K$2:$K$1000,A12,Inventario!$D$2:$D$1000,"<>Internacional") -> 3 | F12: =COUNTIFS(Inventario!$M$2:$M$1000,"*"&A12&"*",Inventario!$D$2:$D$1000,"<>Internacional") -> 3 | G12: =COUNTIFS(Inventario!$M$2:$M$1000,"*"&A12&"*",Inventario!$D$2:$D$1000,"<>Internacional",Inventario!$Q$2:$Q$1000,"4*") -> 0 | H12: =COUNTIFS(Inventario!$M$2:$M$1000,"*"&A12&"*",Inventario!$D$2:$D$1000,"<>Internacional",Inventario!$Q$2:$Q$1000,"3*") -> 1 | I12: =COUNTIFS(Inventario!$M$2:$M$1000,"*"&A12&"*",Inventario!$D$2:$D$1000,"<>Internacional",Inventario!$W$2:$W$1000,"Sí") -> 1 | J12: =COUNTIFS(Inventario!$M$2:$M$1000,"*"&A12&"*",Inventario!$D$2:$D$1000,"Internacional") -> 0 | K12: =IF(F12=0,IF(J12>0,"Sin cobertura nacional (solo internacional)","Sin cobertura"),IF(E12=0,"Cobertura indirecta",IF(G12=0,"Cobertura sin análisis","Cobertura con análisis"))) -> Cobertura sin análisis | L12: =IF(E12>=5,"Alta concentración: revisar superposición","") | M12: =HYPERLINK("https://catalogodatos.gub.uy/dataset?q="&SUBSTITUTE('Taxonomía temas'!J9," ","+"),"Buscar datasets") -> Buscar datasets
A13: ='Taxonomía temas'!A10 -> T09 | B13: ='Taxonomía temas'!D10 -> Economía y producción | C13: ='Taxonomía temas'!E10 -> Precios, consumo y construcción | D13: ='Taxonomía temas'!F10 -> 12 | E13: =COUNTIFS(Inventario!$K$2:$K$1000,A13,Inventario!$D$2:$D$1000,"<>Internacional") -> 3 | F13: =COUNTIFS(Inventario!$M$2:$M$1000,"*"&A13&"*",Inventario!$D$2:$D$1000,"<>Internacional") -> 9 | G13: =COUNTIFS(Inventario!$M$2:$M$1000,"*"&A13&"*",Inventario!$D$2:$D$1000,"<>Internacional",Inventario!$Q$2:$Q$1000,"4*") -> 4 | H13: =COUNTIFS(Inventario!$M$2:$M$1000,"*"&A13&"*",Inventario!$D$2:$D$1000,"<>Internacional",Inventario!$Q$2:$Q$1000,"3*") -> 4 | I13: =COUNTIFS(Inventario!$M$2:$M$1000,"*"&A13&"*",Inventario!$D$2:$D$1000,"<>Internacional",Inventario!$W$2:$W$1000,"Sí") -> 2 | J13: =COUNTIFS(Inventario!$M$2:$M$1000,"*"&A13&"*",Inventario!$D$2:$D$1000,"Internacional") -> 0 | K13: =IF(F13=0,IF(J13>0,"Sin cobertura nacional (solo internacional)","Sin cobertura"),IF(E13=0,"Cobertura indirecta",IF(G13=0,"Cobertura sin análisis","Cobertura con análisis"))) -> Cobertura con análisis | L13: =IF(E13>=5,"Alta concentración: revisar superposición","") | M13: =HYPERLINK("https://catalogodatos.gub.uy/dataset?q="&SUBSTITUTE('Taxonomía temas'!J10," ","+"),"Buscar datasets") -> Buscar datasets
A14: ='Taxonomía temas'!A11 -> T10 | B14: ='Taxonomía temas'!D11 -> Ciencia, tecnología e innovación | C14: ='Taxonomía temas'!E11 -> Telecomunicaciones y sociedad digital | D14: ='Taxonomía temas'!F11 -> 9 | E14: =COUNTIFS(Inventario!$K$2:$K$1000,A14,Inventario!$D$2:$D$1000,"<>Internacional") -> 2 | F14: =COUNTIFS(Inventario!$M$2:$M$1000,"*"&A14&"*",Inventario!$D$2:$D$1000,"<>Internacional") -> 2 | G14: =COUNTIFS(Inventario!$M$2:$M$1000,"*"&A14&"*",Inventario!$D$2:$D$1000,"<>Internacional",Inventario!$Q$2:$Q$1000,"4*") -> 1 | H14: =COUNTIFS(Inventario!$M$2:$M$1000,"*"&A14&"*",Inventario!$D$2:$D$1000,"<>Internacional",Inventario!$Q$2:$Q$1000,"3*") -> 0 | I14: =COUNTIFS(Inventario!$M$2:$M$1000,"*"&A14&"*",Inventario!$D$2:$D$1000,"<>Internacional",Inventario!$W$2:$W$1000,"Sí") -> 2 | J14: =COUNTIFS(Inventario!$M$2:$M$1000,"*"&A14&"*",Inventario!$D$2:$D$1000,"Internacional") -> 3 | K14: =IF(F14=0,IF(J14>0,"Sin cobertura nacional (solo internacional)","Sin cobertura"),IF(E14=0,"Cobertura indirecta",IF(G14=0,"Cobertura sin análisis","Cobertura con análisis"))) -> Cobertura con análisis | L14: =IF(E14>=5,"Alta concentración: revisar superposición","") | M14: =HYPERLINK("https://catalogodatos.gub.uy/dataset?q="&SUBSTITUTE('Taxonomía temas'!J11," ","+"),"Buscar datasets") -> Buscar datasets
